Workbook
Name NativeTimeline_Date: #N/A
Name Slicer_Category: #N/A
Name Slicer_Customer_Segment: #N/A
Name Slicer_Payment_Method: #N/A
Name Slicer_Region: #N/A

Sheet Raw Data
A1: Transaction_ID | B1: Date | C1: Customer_ID | D1: Customer_Name | E1: Product_ID | F1: Product_Name | G1: Category | H1: Quantity | I1: Unit_Price | J1: Payment_Method | K1: Region | L1: Customer_Segment | M1: Customer_Since | N1: Total_Amount | O1: Create_Timestamp | P1: Transaction_Level
A2: TRX0155 | B2: 45393 | C2: CUST023 | D2: Paul Baker | E2: P009 | F2: Monitor | G2: Electronics | H2: 3 | I2: 249.99 | J2: Cash | K2: Central | L2: Basic | M2: 44425 | N2: 749.97 | O2: =IF(A2<>"",NOW(),"") -> 46324.555 | P2: =IF(N2>=1000,"High",IF(N2>=500,"Medium","Low")) -> Medium
A3: TRX0023 | B3: 45396 | C3: CUST013 | D3: Joseph Jackson | E3: P009 | F3: Monitor | G3: Electronics | H3: 3 | I3: 249.99 | J3: Credit Card | K3: Central | L3: Premium | M3: 44575 | N3: 749.97 | O3: =IF(A3<>"",NOW(),"") -> 46324.555 | P3: =IF(N3>=1000,"High",IF(N3>=500,"Medium","Low")) -> Medium
A4: TRX0139 | B4: 45399 | C4: CUST021 | D4: Kevin Scott | E4: P005 | F4: Blender | G4: Appliances | H4: 3 | I4: 59.99 | J4: PayPal | K4: South | L4: Standard | M4: 45262 | N4: 179.97 | O4: =IF(A4<>"",NOW(),"") -> 46324.555 | P4: =IF(N4>=1000,"High",IF(N4>=500,"Medium","Low")) -> Low
A5: TRX0043 | B5: 45400 | C5: CUST046 | D5: Kathleen Bennett | E5: P005 | F5: Blender | G5: Appliances | H5: 3 | I5: 59.99 | J5: Cash | K5: North | L5: Premium | M5: 45114 | N5: 179.97 | O5: =IF(A5<>"",NOW(),"") -> 46324.555 | P5: =IF(N5>=1000,"High",IF(N5>=500,"Medium","Low")) -> Low
A6: TRX0212 | B6: 45400 | C6: CUST003 | D6: Michael Brown | E6: P008 | F6: Bookshelf | G6: Furniture | H6: 5 | I6: 149.99 | J6: Credit Card | K6: North | L6: Premium | M6: 45295 | N6: 749.95 | O6: =IF(A6<>"",NOW(),"") -> 46324.555 | P6: =IF(N6>=1000,"High",IF(N6>=500,"Medium","Low")) -> Medium
A7: TRX0092 | B7: 45403 | C7: CUST024 | D7: Dorothy Nelson | E7: P005 | F7: Blender | G7: Appliances | H7: 2 | I7: 59.99 | J7: Cash | K7: West | L7: Standard | M7: 44746 | N7: 119.98 | O7: =IF(A7<>"",NOW(),"") -> 46324.555 | P7: =IF(N7>=1000,"High",IF(N7>=500,"Medium","Low")) -> Low
A8: TRX0193 | B8: 45403 | C8: CUST024 | D8: Dorothy Nelson | E8: P003 | F8: Headphones | G8: Electronics | H8: 5 | I8: 149.99 | J8: Credit Card | K8: Central | L8: Standard | M8: 44418 | N8: 749.95 | O8: =IF(A8<>"",NOW(),"") -> 46324.555 | P8: =IF(N8>=1000,"High",IF(N8>=500,"Medium","Low")) -> Medium
A9: TRX0240 | B9: 45403 | C9: CUST017 | D9: Charles Allen | E9: P005 | F9: Blender | G9: Appliances | H9: 3 | I9: 59.99 | J9: Debit Card | K9: South | L9: Basic | M9: 45007 | N9: 179.97 | O9: =IF(A9<>"",NOW(),"") -> 46324.555 | P9: =IF(N9>=1000,"High",IF(N9>=500,"Medium","Low")) -> Low
A10: TRX0135 | B10: 45405 | C10: CUST009 | D10: Robert Thomas | E10: P001 | F10: Laptop | G10: Electronics | H10: 3 | I10: 899.99 | J10: PayPal | K10: East | L10: Standard | M10: 45299 | N10: 2699.97 | O10: =IF(A10<>"",NOW(),"") -> 46324.555 | P10: =IF(N10>=1000,"High",IF(N10>=500,"Medium","Low")) -> High
A11: TRX0185 | B11: 45408 | C11: CUST026 | D11: Karen Hill | E11: P005 | F11: Blender | G11: Appliances | H11: 3 | I11: 59.99 | J11: Cash | K11: West | L11: Premium | M11: 45207 | N11: 179.97 | O11: =IF(A11<>"",NOW(),"") -> 46324.555 | P11: =IF(N11>=1000,"High",IF(N11>=500,"Medium","Low")) -> Low
A12: TRX0138 | B12: 45408 | C12: CUST022 | D12: Susan Green | E12: P008 | F12: Bookshelf | G12: Furniture | H12: 1 | I12: 149.99 | J12: Credit Card | K12: West | L12: Standard | M12: 45103 | N12: 149.99 | O12: =IF(A12<>"",NOW(),"") -> 46324.555 | P12: =IF(N12>=1000,"High",IF(N12>=500,"Medium","Low")) -> Low
A13: TRX0209 | B13: 45408 | C13: CUST046 | D13: Kathleen Bennett | E13: P008 | F13: Bookshelf | G13: Furniture | H13: 5 | I13: 149.99 | J13: Debit Card | K13: North | L13: Basic | M13: 44830 | N13: 749.95 | O13: =IF(A13<>"",NOW(),"") -> 46324.555 | P13: =IF(N13>=1000,"High",IF(N13>=500,"Medium","Low")) -> Medium
... A251: TRX0064 | B251: 45758 | C251: CUST031 | D251: Steven Turner | E251: P010 | F251: Keyboard | G251: Electronics | H251: 3 | I251: 89.99 | J251: Debit Card | K251: North | L251: Premium | M251: 44878 | N251: 269.97 | O251: =IF(A251<>"",NOW(),"") -> 46324.555 | P251: =IF(N251>=1000,"High",IF(N251>=500,"Medium","Low")) -> Low

Sheet Analysis
A1: DATA INTELLIGENCE ANALYSIS
A3: Current Date | B3: =TODAY() -> 46324
A4: Current Date & Time | B4: =NOW() -> 46324.555 | I4: Filter Electronics transactions | Z4: Filter by Region | AQ4: Filter using two conditions | BH4: Filter using multiple regions
A7: Customer Name | B7: Customer Since | C7: Customer Tenure (Years) | D7: Customer Tenure (Months) | E7: Month End Date | I7: {=_xlfn._xlws.FILTER(tblTransactions[],tblTransactions[Category]="Electronics","No Records Found")} -> TRX0155 | J7: 45393 | K7: CUST023 | L7: Paul Baker | M7: P009 | N7: Monitor | O7: Electronics | P7: 3 | Q7: 249.99 | R7: Cash | S7: Central | T7: Basic | U7: 44425 | V7: 749.97 | W7: 46324.555 | X7: Medium | Z7: {=_xlfn._xlws.FILTER(tblTransactions[],tblTransactions[Region]="North","No Records Found")} -> TRX0043 | AA7: 45400 | AB7: CUST046 | AC7: Kathleen Bennett | AD7: P005 | AE7: Blender | AF7: Appliances | AG7: 3 | AH7: 59.99 | AI7: Cash | AJ7: North | AK7: Premium | AL7: 45114 | AM7: 179.97 | AN7: 46324.555 | AO7: Low | AQ7: {=_xlfn._xlws.FILTER(tblTransactions[],(tblTransactions[Category]="Electronics")*(tblTransactions[Region]="North"),"No Records Found")} -> TRX0230 | AR7: 45409 | AS7: CUST027 | AT7: George Adams | AU7: P001 | AV7: Laptop | AW7: Electronics | AX7: 1 | AY7: 899.99 | AZ7: Debit Card | BA7: North | BB7: Standard | BC7: 44920 | BD7: 899.99 | BE7: 46324.555 | BF7: Medium | BH7: {=_xlfn._xlws.FILTER(tblTransactions[],(tblTransactions[Region]="North")+(tblTransactions[Region]="South"),"No Records Found")} -> TRX0139 | BI7: 45399 | BJ7: CUST021 | BK7: Kevin Scott | BL7: P005 | BM7: Blender | BN7: Appliances | BO7: 3 | BP7: 59.99 | BQ7: PayPal | BR7: South | BS7: Standard | BT7: 45262 | BU7: 179.97 | BV7: 46324.555 | BW7: Low
A8: ='Raw Data'!D2 -> Paul Baker | B8: ='Raw Data'!M2 -> 44425 | C8: =DATEDIF(B8,TODAY(),"Y") -> 5 | D8: =DATEDIF(B8,$B$3,"M") -> 62 | E8: =EOMONTH(B8,0) -> 44439 | I8: TRX0023 | J8: 45396 | K8: CUST013 | L8: Joseph Jackson | M8: P009 | N8: Monitor | O8: Electronics | P8: 3 | Q8: 249.99 | R8: Credit Card | S8: Central | T8: Premium | U8: 44575 | V8: 749.97 | W8: 46324.555 | X8: Medium | Z8: TRX0212 | AA8: 45400 | AB8: CUST003 | AC8: Michael Brown | AD8: P008 | AE8: Bookshelf | AF8: Furniture | AG8: 5 | AH8: 149.99 | AI8: Credit Card | AJ8: North | AK8: Premium | AL8: 45295 | AM8: 749.95 | AN8: 46324.555 | AO8: Medium | AQ8: TRX0134 | AR8: 45410 | AS8: CUST010 | AT8: Maria Garcia | AU8: P002 | AV8: Smartphone | AW8: Electronics | AX8: 2 | AY8: 699.99 | AZ8: Cash | BA8: North | BB8: Basic | BC8: 44781 | BD8: 1399.98 | BE8: 46324.555 | BF8: High | BH8: TRX0043 | BI8: 45400 | BJ8: CUST046 | BK8: Kathleen Bennett | BL8: P005 | BM8: Blender | BN8: Appliances | BO8: 3 | BP8: 59.99 | BQ8: Cash | BR8: North | BS8: Premium | BT8: 45114 | BU8: 179.97 | BV8: 46324.555 | BW8: Low
A9: ='Raw Data'!D3 -> Joseph Jackson | B9: ='Raw Data'!M3 -> 44575 | C9: =DATEDIF(B9,TODAY(),"Y") -> 4 | D9: =DATEDIF(B9,$B$3,"M") -> 57 | E9: =EOMONTH(B9,0) -> 44592 | I9: TRX0193 | J9: 45403 | K9: CUST024 | L9: Dorothy Nelson | M9: P003 | N9: Headphones | O9: Electronics | P9: 5 | Q9: 149.99 | R9: Credit Card | S9: Central | T9: Standard | U9: 44418 | V9: 749.95 | W9: 46324.555 | X9: Medium | Z9: TRX0209 | AA9: 45408 | AB9: CUST046 | AC9: Kathleen Bennett | AD9: P008 | AE9: Bookshelf | AF9: Furniture | AG9: 5 | AH9: 149.99 | AI9: Debit Card | AJ9: North | AK9: Basic | AL9: 44830 | AM9: 749.95 | AN9: 46324.555 | AO9: Medium | AQ9: TRX0222 | AR9: 45410 | AS9: CUST048 | AT9: Virginia Sanders | AU9: P009 | AV9: Monitor | AW9: Electronics | AX9: 3 | AY9: 249.99 | AZ9: Credit Card | BA9: North | BB9: Premium | BC9: 45224 | BD9: 749.97 | BE9: 46324.555 | BF9: Medium | BH9: TRX0212 | BI9: 45400 | BJ9: CUST003 | BK9: Michael Brown | BL9: P008 | BM9: Bookshelf | BN9: Furniture | BO9: 5 | BP9: 149.99 | BQ9: Credit Card | BR9: North | BS9: Premium | BT9: 45295 | BU9: 749.95 | BV9: 46324.555 | BW9: Medium
A10: ='Raw Data'!D4 -> Kevin Scott | B10: ='Raw Data'!M4 -> 45262 | C10: =DATEDIF(B10,TODAY(),"Y") -> 2 | D10: =DATEDIF(B10,$B$3,"M") -> 34 | E10: =EOMONTH(B10,0) -> 45291 | I10: TRX0135 | J10: 45405 | K10: CUST009 | L10: Robert Thomas | M10: P001 | N10: Laptop | O10: Electronics | P10: 3 | Q10: 899.99 | R10: PayPal | S10: East | T10: Standard | U10: 45299 | V10: 2699.97 | W10: 46324.555 | X10: High | Z10: TRX0246 | AA10: 45408 | AB10: CUST041 | AC10: Peter Richardson | AD10: P008 | AE10: Bookshelf | AF10: Furniture | AG10: 3 | AH10: 149.99 | AI10: Cash | AJ10: North | AK10: Premium | AL10: 44806 | AM10: 449.97 | AN10: 46324.555 | AO10: Low | AQ10: TRX0204 | AR10: 45415 | AS10: CUST044 | AT10: Cynthia Price | AU10: P009 | AV10: Monitor | AW10: Electronics | AX10: 4 | AY10: 249.99 | AZ10: PayPal | BA10: North | BB10: Standard | BC10: 44468 | BD10: 999.96 | BE10: 46324.555 | BF10: Medium | BH10: TRX0240 | BI10: 45403 | BJ10: CUST017 | BK10: Charles Allen | BL10: P005 | BM10: Blender | BN10: Appliances | BO10: 3 | BP10: 59.99 | BQ10: Debit Card | BR10: South | BS10: Basic | BT10: 45007 | BU10: 179.97 | BV10: 46324.555 | BW10: Low
A11: ='Raw Data'!D5 -> Kathleen Bennett | B11: ='Raw Data'!M5 -> 45114 | C11: =DATEDIF(B11,TODAY(),"Y") -> 3 | D11: =DATEDIF(B11,$B$3,"M") -> 39 | E11: =EOMONTH(B11,0) -> 45138 | I11: TRX0191 | J11: 45409 | K11: CUST038 | L11: Michelle Rogers | M11: P002 | N11: Smartphone | O11: Electronics | P11: 3 | Q11: 699.99 | R11: Credit Card | S11: West | T11: Basic | U11: 44577 | V11: 2099.97 | W11: 46324.555 | X11: High | Z11: TRX0067 | AA11: 45409 | AB11: CUST043 | AC11: Dennis Gray | AD11: P005 | AE11: Blender | AF11: Appliances | AG11: 3 | AH11: 59.99 | AI11: Credit Card | AJ11: North | AK11: Standard | AL11: 45351 | AM11: 179.97 | AN11: 46324.555 | AO11: Low | AQ11: TRX0004 | AR11: 45424 | AS11: CUST012 | AT11: Patricia Moore | AU11: P010 | AV11: Keyboard | AW11: Electronics | AX11: 5 | AY11: 89.99 | AZ11: Cash | BA11: North | BB11: Premium | BC11: 44919 | BD11: 449.95 | BE11: 46324.555 | BF11: Low | BH11: TRX0209 | BI11: 45408 | BJ11: CUST046 | BK11: Kathleen Bennett | BL11: P008 | BM11: Bookshelf | BN11: Furniture | BO11: 5 | BP11: 149.99 | BQ11: Debit Card | BR11: North | BS11: Basic | BT11: 44830 | BU11: 749.95 | BV11: 46324.555 | BW11: Medium
A12: ='Raw Data'!D6 -> Michael Brown | B12: ='Raw Data'!M6 -> 45295 | C12: =DATEDIF(B12,TODAY(),"Y") -> 2 | D12: =DATEDIF(B12,$B$3,"M") -> 33 | E12: =EOMONTH(B12,0) -> 45322 | I12: TRX0230 | J12: 45409 | K12: CUST027 | L12: George Adams | M12: P001 | N12: Laptop | O12: Electronics | P12: 1 | Q12: 899.99 | R12: Debit Card | S12: North | T12: Standard | U12: 44920 | V12: 899.99 | W12: 46324.555 | X12: Medium | Z12: TRX0230 | AA12: 45409 | AB12: CUST027 | AC12: George Adams | AD12: P001 | AE12: Laptop | AF12: Electronics | AG12: 1 | AH12: 899.99 | AI12: Debit Card | AJ12: North | AK12: Standard | AL12: 44920 | AM12: 899.99 | AN12: 46324.555 | AO12: Medium | AQ12: TRX0117 | AR12: 45444 | AS12: CUST017 | AT12: Charles Allen | AU12: P010 | AV12: Keyboard | AW12: Electronics | AX12: 1 | AY12: 89.99 | AZ12: Cash | BA12: North | BB12: Basic | BC12: 45141 | BD12: 89.99 | BE12: 46324.555 | BF12: Low | BH12: TRX0246 | BI12: 45408 | BJ12: CUST041 | BK12: Peter Richardson | BL12: P008 | BM12: Bookshelf | BN12: Furniture | BO12: 3 | BP12: 149.99 | BQ12: Cash | BR12: North | BS12: Premium | BT12: 44806 | BU12: 449.97 | BV12: 46324.555 | BW12: Low
A13: ='Raw Data'!D7 -> Dorothy Nelson | B13: ='Raw Data'!M7 -> 44746 | C13: =DATEDIF(B13,TODAY(),"Y") -> 4 | D13: =DATEDIF(B13,$B$3,"M") -> 51 | E13: =EOMONTH(B13,0) -> 44773 | I13: TRX0134 | J13: 45410 | K13: CUST010 | L13: Maria Garcia | M13: P002 | N13: Smartphone | O13: Electronics | P13: 2 | Q13: 699.99 | R13: Cash | S13: North | T13: Basic | U13: 44781 | V13: 1399.98 | W13: 46324.555 | X13: High | Z13: TRX0049 | AA13: 45410 | AB13: CUST025 | AC13: Mark Carter | AD13: P008 | AE13: Bookshelf | AF13: Furniture | AG13: 4 | AH13: 149.99 | AI13: Debit Card | AJ13: North | AK13: Premium | AL13: 45374 | AM13: 599.96 | AN13: 46324.555 | AO13: Medium | AQ13: TRX0114 | AR13: 45481 | AS13: CUST018 | AT13: Barbara Young | AU13: P010 | AV13: Keyboard | AW13: Electronics | AX13: 5 | AY13: 89.99 | AZ13: Debit Card | BA13: North | BB13: Premium | BC13: 45161 | BD13: 449.95 | BE13: 46324.555 | BF13: Low | BH13: TRX0067 | BI13: 45409 | BJ13: CUST043 | BK13: Dennis Gray | BL13: P005 | BM13: Blender | BN13: Appliances | BO13: 3 | BP13: 59.99 | BQ13: Credit Card | BR13: North | BS13: Standard | BT13: 45351 | BU13: 179.97 | BV13: 46324.555 | BW13: Low
A14: ='Raw Data'!D8 -> Dorothy Nelson | B14: ='Raw Data'!M8 -> 44418 | C14: =DATEDIF(B14,TODAY(),"Y") -> 5 | D14: =DATEDIF(B14,$B$3,"M") -> 62 | E14: =EOMONTH(B14,0) -> 44439 | I14: TRX0122 | J14: 45410 | K14: CUST025 | L14: Mark Carter | M14: P001 | N14: Laptop | O14: Electronics | P14: 4 | Q14: 899.99 | R14: Credit Card | S14: West | T14: Standard | U14: 45327 | V14: 3599.96 | W14: 46324.555 | X14: High | Z14: TRX0134 | AA14: 45410 | AB14: CUST010 | AC14: Maria Garcia | AD14: P002 | AE14: Smartphone | AF14: Electronics | AG14: 2 | AH14: 699.99 | AI14: Cash | AJ14: North | AK14: Basic | AL14: 44781 | AM14: 1399.98 | AN14: 46324.555 | AO14: High | AQ14: TRX0080 | AR14: 45500 | AS14: CUST018 | AT14: Barbara Young | AU14: P009 | AV14: Monitor | AW14: Electronics | AX14: 2 | AY14: 249.99 | AZ14: Cash | BA14: North | BB14: Premium | BC14: 45164 | BD14: 499.98 | BE14: 46324.555 | BF14: Low | BH14: TRX0230 | BI14: 45409 | BJ14: CUST027 | BK14: George Adams | BL14: P001 | BM14: Laptop | BN14: Electronics | BO14: 1 | BP14: 899.99 | BQ14: Debit Card | BR14: North | BS14: Standard | BT14: 44920 | BU14: 899.99 | BV14: 46324.555 | BW14: Medium
A15: ='Raw Data'!D9 -> Charles Allen | B15: ='Raw Data'!M9 -> 45007 | C15: =DATEDIF(B15,TODAY(),"Y") -> 3 | D15: =DATEDIF(B15,$B$3,"M") -> 43 | E15: =EOMONTH(B15,0) -> 45016 | I15: TRX0222 | J15: 45410 | K15: CUST048 | L15: Virginia Sanders | M15: P009 | N15: Monitor | O15: Electronics | P15: 3 | Q15: 249.99 | R15: Credit Card | S15: North | T15: Premium | U15: 45224 | V15: 749.97 | W15: 46324.555 | X15: Medium | Z15: TRX0222 | AA15: 45410 | AB15: CUST048 | AC15: Virginia Sanders | AD15: P009 | AE15: Monitor | AF15: Electronics | AG15: 3 | AH15: 249.99 | AI15: Credit Card | AJ15: North | AK15: Premium | AL15: 45224 | AM15: 749.97 | AN15: 46324.555 | AO15: Medium | AQ15: TRX0217 | AR15: 45503 | AS15: CUST025 | AT15: Mark Carter | AU15: P002 | AV15: Smartphone | AW15: Electronics | AX15: 2 | AY15: 699.99 | AZ15: Credit Card | BA15: North | BB15: Premium | BC15: 44999 | BD15: 1399.98 | BE15: 46324.555 | BF15: High | BH15: TRX0049 | BI15: 45410 | BJ15: CUST025 | BK15: Mark Carter | BL15: P008 | BM15: Bookshelf | BN15: Furniture | BO15: 4 | BP15: 149.99 | BQ15: Debit Card | BR15: North | BS15: Premium | BT15: 45374 | BU15: 599.96 | BV15: 46324.555 | BW15: Medium
A16: ='Raw Data'!D10 -> Robert Thomas | B16: ='Raw Data'!M10 -> 45299 | C16: =DATEDIF(B16,TODAY(),"Y") -> 2 | D16: =DATEDIF(B16,$B$3,"M") -> 33 | E16: =EOMONTH(B16,0) -> 45322 | I16: TRX0231 | J16: 45412 | K16: CUST018 | L16: Barbara Young | M16: P002 | N16: Smartphone | O16: Electronics | P16: 5 | Q16: 699.99 | R16: Cash | S16: West | T16: Basic | U16: 45167 | V16: 3499.95 | W16: 46324.555 | X16: High | Z16: TRX0204 | AA16: 45415 | AB16: CUST044 | AC16: Cynthia Price | AD16: P009 | AE16: Monitor | AF16: Electronics | AG16: 4 | AH16: 249.99 | AI16: PayPal | AJ16: North | AK16: Standard | AL16: 44468 | AM16: 999.96 | AN16: 46324.555 | AO16: Medium | AQ16: TRX0101 | AR16: 45513 | AS16: CUST010 | AT16: Maria Garcia | AU16: P010 | AV16: Keyboard | AW16: Electronics | AX16: 1 | AY16: 89.99 | AZ16: Credit Card | BA16: North | BB16: Standard | BC16: 45393 | BD16: 89.99 | BE16: 46324.555 | BF16: Low | BH16: TRX0134 | BI16: 45410 | BJ16: CUST010 | BK16: Maria Garcia | BL16: P002 | BM16: Smartphone | BN16: Electronics | BO16: 2 | BP16: 699.99 | BQ16: Cash | BR16: North | BS16: Basic | BT16: 44781 | BU16: 1399.98 | BV16: 46324.555 | BW16: High
A17: ='Raw Data'!D11 -> Karen Hill | B17: ='Raw Data'!M11 -> 45207 | C17: =DATEDIF(B17,TODAY(),"Y") -> 3 | D17: =DATEDIF(B17,$B$3,"M") -> 36 | E17: =EOMONTH(B17,0) -> 45230 | I17: TRX0239 | J17: 45413 | K17: CUST012 | L17: Patricia Moore | M17: P002 | N17: Smartphone | O17: Electronics | P17: 4 | Q17: 699.99 | R17: Cash | S17: East | T17: Standard | U17: 44409 | V17: 2799.96 | W17: 46324.555 | X17: High | Z17: TRX0004 | AA17: 45424 | AB17: CUST012 | AC17: Patricia Moore | AD17: P010 | AE17: Keyboard | AF17: Electronics | AG17: 5 | AH17: 89.99 | AI17: Cash | AJ17: North | AK17: Premium | AL17: 44919 | AM17: 449.95 | AN17: 46324.555 | AO17: Low | AQ17: TRX0098 | AR17: 45517 | AS17: CUST026 | AT17: Karen Hill | AU17: P009 | AV17: Monitor | AW17: Electronics | AX17: 3 | AY17: 249.99 | AZ17: PayPal | BA17: North | BB17: Premium | BC17: 44465 | BD17: 749.97 | BE17: 46324.555 | BF17: Medium | BH17: TRX0222 | BI17: 45410 | BJ17: CUST048 | BK17: Virginia Sanders | BL17: P009 | BM17: Monitor | BN17: Electronics | BO17: 3 | BP17: 249.99 | BQ17: Credit Card | BR17: North | BS17: Premium | BT17: 45224 | BU17: 749.97 | BV17: 46324.555 | BW17: Medium
A18: ='Raw Data'!D12 -> Susan Green | B18: ='Raw Data'!M12 -> 45103 | C18: =DATEDIF(B18,TODAY(),"Y") -> 3 | D18: =DATEDIF(B18,$B$3,"M") -> 40 | E18: =EOMONTH(B18,0) -> 45107 | I18: TRX0204 | J18: 45415 | K18: CUST044 | L18: Cynthia Price | M18: P009 | N18: Monitor | O18: Electronics | P18: 4 | Q18: 249.99 | R18: PayPal | S18: North | T18: Standard | U18: 44468 | V18: 999.96 | W18: 46324.555 | X18: Medium | Z18: TRX0245 | AA18: 45438 | AB18: CUST031 | AC18: Steven Turner | AD18: P006 | AE18: Office Chair | AF18: Furniture | AG18: 3 | AH18: 199.99 | AI18: Credit Card | AJ18: North | AK18: Premium | AL18: 45292 | AM18: 599.97 | AN18: 46324.555 | AO18: Medium | AQ18: TRX0248 | AR18: 45534 | AS18: CUST032 | AT18: Sandra Phillips | AU18: P002 | AV18: Smartphone | AW18: Electronics | AX18: 2 | AY18: 699.99 | AZ18: Credit Card | BA18: North | BB18: Premium | BC18: 44421 | BD18: 1399.98 | BE18: 46324.555 | BF18: High | BH18: TRX0204 | BI18: 45415 | BJ18: CUST044 | BK18: Cynthia Price | BL18: P009 | BM18: Monitor | BN18: Electronics | BO18: 4 | BP18: 249.99 | BQ18: PayPal | BR18: North | BS18: Standard | BT18: 44468 | BU18: 999.96 | BV18: 46324.555 | BW18: Medium
A19: ='Raw Data'!D13 -> Kathleen Bennett | B19: ='Raw Data'!M13 -> 44830 | C19: =DATEDIF(B19,TODAY(),"Y") -> 4 | D19: =DATEDIF(B19,$B$3,"M") -> 49 | E19: =EOMONTH(B19,0) -> 44834 | I19: TRX0071 | J19: 45422 | K19: CUST036 | L19: Nancy Collins | M19: P009 | N19: Monitor | O19: Electronics | P19: 5 | Q19: 249.99 | R19: Credit Card | S19: West | T19: Standard | U19: 44525 | V19: 1249.95 | W19: 46324.555 | X19: High | Z19: TRX0042 | AA19: 45443 | AB19: CUST019 | AC19: Daniel King | AD19: P004 | AE19: Coffee Maker | AF19: Appliances | AG19: 1 | AH19: 79.99 | AI19: Cash | AJ19: North | AK19: Standard | AL19: 44917 | AM19: 79.99 | AN19: 46324.555 | AO19: Low | AQ19: TRX0074 | AR19: 45537 | AS19: CUST023 | AT19: Paul Baker | AU19: P009 | AV19: Monitor | AW19: Electronics | AX19: 1 | AY19: 249.99 | AZ19: Debit Card | BA19: North | BB19: Premium | BC19: 45332 | BD19: 249.99 | BE19: 46324.555 | BF19: Low | BH19: TRX0004 | BI19: 45424 | BJ19: CUST012 | BK19: Patricia Moore | BL19: P010 | BM19: Keyboard | BN19: Electronics | BO19: 5 | BP19: 89.99 | BQ19: Cash | BR19: North | BS19: Premium | BT19: 44919 | BU19: 449.95 | BV19: 46324.555 | BW19: Low
... A42: ='Raw Data'!D36 -> Patricia Moore | B42: ='Raw Data'!M36 -> 44824 | C42: =DATEDIF(B42,TODAY(),"Y") -> 4 | D42: =DATEDIF(B42,$B$3,"M") -> 49 | E42: =EOMONTH(B42,0) -> 44834 | I42: TRX0162 | J42: 45496 | K42: CUST040 | L42: Sharon Butler | M42: P001 | N42: Laptop | O42: Electronics | P42: 1 | Q42: 899.99 | R42: Cash | S42: Central | T42: Standard | U42: 45179 | V42: 899.99 | W42: 46324.555 | X42: Medium | Z42: TRX0060 | AA42: 45603 | AB42: CUST012 | AC42: Patricia Moore | AD42: P010 | AE42: Keyboard | AF42: Electronics | AG42: 3 | AH42: 89.99 | AI42: Credit Card | AJ42: North | AK42: Premium | AL42: 44420 | AM42: 269.97 | AN42: 46324.555 | AO42: Low | AQ42: TRX0064 | AR42: 45758 | AS42: CUST031 | AT42: Steven Turner | AU42: P010 | AV42: Keyboard | AW42: Electronics | AX42: 3 | AY42: 89.99 | AZ42: Debit Card | BA42: North | BB42: Premium | BC42: 44878 | BD42: 269.97 | BE42: 46324.555 | BF42: Low | BH42: TRX0249 | BI42: 45504 | BJ42: CUST030 | BK42: Helen Roberts | BL42: P001 | BM42: Laptop | BN42: Electronics | BO42: 4 | BP42: 899.99 | BQ42: Debit Card | BR42: South | BS42: Standard | BT42: 44523 | BU42: 3599.96 | BV42: 46324.555 | BW42: High
A43: ='Raw Data'!D37 -> Lisa Anderson | B43: ='Raw Data'!M37 -> 45046 | C43: =DATEDIF(B43,TODAY(),"Y") -> 3 | D43: =DATEDIF(B43,$B$3,"M") -> 41 | E43: =EOMONTH(B43,0) -> 45046 | I43: TRX0244 | J43: 45497 | K43: CUST013 | L43: Joseph Jackson | M43: P001 | N43: Laptop | O43: Electronics | P43: 5 | Q43: 899.99 | R43: Debit Card | S43: South | T43: Standard | U43: 44899 | V43: 4499.95 | W43: 46324.555 | X43: High | Z43: TRX0090 | AA43: 45605 | AB43: CUST020 | AC43: Margaret Wright | AD43: P009 | AE43: Monitor | AF43: Electronics | AG43: 1 | AH43: 249.99 | AI43: Credit Card | AJ43: North | AK43: Premium | AL43: 44828 | AM43: 249.99 | AN43: 46324.555 | AO43: Low | BH43: TRX0101 | BI43: 45513 | BJ43: CUST010 | BK43: Maria Garcia | BL43: P010 | BM43: Keyboard | BN43: Electronics | BO43: 1 | BP43: 89.99 | BQ43: Credit Card | BR43: North | BS43: Standard | BT43: 45393 | BU43: 89.99 | BV43: 46324.555 | BW43: Low
A44: ='Raw Data'!D38 -> Steven Turner | B44: ='Raw Data'!M38 -> 45292 | C44: =DATEDIF(B44,TODAY(),"Y") -> 2 | D44: =DATEDIF(B44,$B$3,"M") -> 33 | E44: =EOMONTH(B44,0) -> 45322 | I44: TRX0215 | J44: 45498 | K44: CUST047 | L44: Gerald Murphy | M44: P009 | N44: Monitor | O44: Electronics | P44: 4 | Q44: 249.99 | R44: Debit Card | S44: Central | T44: Standard | U44: 45127 | V44: 999.96 | W44: 46324.555 | X44: Medium | Z44: TRX0035 | AA44: 45607 | AB44: CUST041 | AC44: Peter Richardson | AD44: P003 | AE44: Headphones | AF44: Electronics | AG44: 3 | AH44: 149.99 | AI44: Cash | AJ44: North | AK44: Basic | AL44: 44769 | AM44: 449.97 | AN44: 46324.555 | AO44: Low | BH44: TRX0205 | BI44: 45515 | BJ44: CUST025 | BK44: Mark Carter | BL44: P007 | BM44: Desk | BN44: Furniture | BO44: 5 | BP44: 299.99 | BQ44: Credit Card | BR44: North | BS44: Basic | BT44: 44965 | BU44: 1499.95 | BV44: 46324.555 | BW44: High
A45: ='Raw Data'!D39 -> Jennifer Taylor | B45: ='Raw Data'!M39 -> 44407 | C45: =DATEDIF(B45,TODAY(),"Y") -> 5 | D45: =DATEDIF(B45,$B$3,"M") -> 62 | E45: =EOMONTH(B45,0) -> 44408 | I45: TRX0080 | J45: 45500 | K45: CUST018 | L45: Barbara Young | M45: P009 | N45: Monitor | O45: Electronics | P45: 2 | Q45: 249.99 | R45: Cash | S45: North | T45: Premium | U45: 45164 | V45: 499.98 | W45: 46324.555 | X45: Low | Z45: TRX0073 | AA45: 45613 | AB45: CUST032 | AC45: Sandra Phillips | AD45: P008 | AE45: Bookshelf | AF45: Furniture | AG45: 5 | AH45: 149.99 | AI45: Cash | AJ45: North | AK45: Basic | AL45: 44869 | AM45: 749.95 | AN45: 46324.555 | AO45: Medium | BH45: TRX0020 | BI45: 45517 | BJ45: CUST007 | BK45: David Martinez | BL45: P003 | BM45: Headphones | BN45: Electronics | BO45: 4 | BP45: 149.99 | BQ45: Debit Card | BR45: South | BS45: Premium | BT45: 44820 | BU45: 599.96 | BV45: 46324.555 | BW45: Medium
A46: ='Raw Data'!D40 -> Harry Morgan | B46: ='Raw Data'!M40 -> 45120 | C46: =DATEDIF(B46,TODAY(),"Y") -> 3 | D46: =DATEDIF(B46,$B$3,"M") -> 39 | E46: =EOMONTH(B46,0) -> 45138 | I46: TRX0157 | J46: 45501 | K46: CUST025 | L46: Mark Carter | M46: P010 | N46: Keyboard | O46: Electronics | P46: 2 | Q46: 89.99 | R46: PayPal | S46: South | T46: Basic | U46: 44976 | V46: 179.98 | W46: 46324.555 | X46: Low | Z46: TRX0012 | AA46: 45622 | AB46: CUST045 | AC46: Douglas Watson | AD46: P009 | AE46: Monitor | AF46: Electronics | AG46: 5 | AH46: 249.99 | AI46: Credit Card | AJ46: North | AK46: Basic | AL46: 44873 | AM46: 1249.95 | AN46: 46324.555 | AO46: High | BH46: TRX0098 | BI46: 45517 | BJ46: CUST026 | BK46: Karen Hill | BL46: P009 | BM46: Monitor | BN46: Electronics | BO46: 3 | BP46: 249.99 | BQ46: PayPal | BR46: North | BS46: Premium | BT46: 44465 | BU46: 749.97 | BV46: 46324.555 | BW46: Medium
A47: ='Raw Data'!D41 -> Daniel King | B47: ='Raw Data'!M41 -> 44917 | C47: =DATEDIF(B47,TODAY(),"Y") -> 3 | D47: =DATEDIF(B47,$B$3,"M") -> 46 | E47: =EOMONTH(B47,0) -> 44926 | I47: TRX0217 | J47: 45503 | K47: CUST025 | L47: Mark Carter | M47: P002 | N47: Smartphone | O47: Electronics | P47: 2 | Q47: 699.99 | R47: Credit Card | S47: North | T47: Premium | U47: 44999 | V47: 1399.98 | W47: 46324.555 | X47: High | Z47: TRX0066 | AA47: 45630 | AB47: CUST024 | AC47: Dorothy Nelson | AD47: P002 | AE47: Smartphone | AF47: Electronics | AG47: 4 | AH47: 699.99 | AI47: Credit Card | AJ47: North | AK47: Premium | AL47: 44703 | AM47: 2799.96 | AN47: 46324.555 | AO47: High | BH47: TRX0247 | BI47: 45517 | BJ47: CUST046 | BK47: Kathleen Bennett | BL47: P006 | BM47: Office Chair | BN47: Furniture | BO47: 4 | BP47: 199.99 | BQ47: Cash | BR47: North | BS47: Standard | BT47: 44458 | BU47: 799.96 | BV47: 46324.555 | BW47: Medium
A48: ='Raw Data'!D42 -> Sharon Butler | B48: ='Raw Data'!M42 -> 45390 | C48: =DATEDIF(B48,TODAY(),"Y") -> 2 | D48: =DATEDIF(B48,$B$3,"M") -> 30 | E48: =EOMONTH(B48,0) -> 45412 | I48: TRX0249 | J48: 45504 | K48: CUST030 | L48: Helen Roberts | M48: P001 | N48: Laptop | O48: Electronics | P48: 4 | Q48: 899.99 | R48: Debit Card | S48: South | T48: Standard | U48: 44523 | V48: 3599.96 | W48: 46324.555 | X48: High | Z48: TRX0032 | AA48: 45638 | AB48: CUST041 | AC48: Peter Richardson | AD48: P001 | AE48: Laptop | AF48: Electronics | AG48: 2 | AH48: 899.99 | AI48: Cash | AJ48: North | AK48: Basic | AL48: 44406 | AM48: 1799.98 | AN48: 46324.555 | AO48: High | BH48: TRX0027 | BI48: 45519 | BJ48: CUST028 | BK48: Betty Campbell | BL48: P006 | BM48: Office Chair | BN48: Furniture | BO48: 5 | BP48: 199.99 | BQ48: Cash | BR48: North | BS48: Premium | BT48: 44991 | BU48: 999.95 | BV48: 46324.555 | BW48: Medium
A49: ='Raw Data'!D43 -> Charles Allen | B49: ='Raw Data'!M43 -> 45141 | C49: =DATEDIF(B49,TODAY(),"Y") -> 3 | D49: =DATEDIF(B49,$B$3,"M") -> 38 | E49: =EOMONTH(B49,0) -> 45169 | I49: TRX0101 | J49: 45513 | K49: CUST010 | L49: Maria Garcia | M49: P010 | N49: Keyboard | O49: Electronics | P49: 1 | Q49: 89.99 | R49: Credit Card | S49: North | T49: Standard | U49: 45393 | V49: 89.99 | W49: 46324.555 | X49: Low | Z49: TRX0008 | AA49: 45648 | AB49: CUST007 | AC49: David Martinez | AD49: P008 | AE49: Bookshelf | AF49: Furniture | AG49: 3 | AH49: 149.99 | AI49: Debit Card | AJ49: North | AK49: Standard | AL49: 44522 | AM49: 449.97 | AN49: 46324.555 | AO49: Low | BH49: TRX0037 | BI49: 45528 | BJ49: CUST035 | BK49: Harry Morgan | BL49: P009 | BM49: Monitor | BN49: Electronics | BO49: 2 | BP49: 249.99 | BQ49: Cash | BR49: South | BS49: Standard | BT49: 44572 | BU49: 499.98 | BV49: 46324.555 | BW49: Low
A50: ='Raw Data'!D44 -> Sarah Davis | B50: ='Raw Data'!M44 -> 44587 | C50: =DATEDIF(B50,TODAY(),"Y") -> 4 | D50: =DATEDIF(B50,$B$3,"M") -> 57 | E50: =EOMONTH(B50,0) -> 44592 | I50: TRX0020 | J50: 45517 | K50: CUST007 | L50: David Martinez | M50: P003 | N50: Headphones | O50: Electronics | P50: 4 | Q50: 149.99 | R50: Debit Card | S50: South | T50: Premium | U50: 44820 | V50: 599.96 | W50: 46324.555 | X50: Medium | Z50: TRX0207 | AA50: 45657 | AB50: CUST025 | AC50: Mark Carter | AD50: P001 | AE50: Laptop | AF50: Electronics | AG50: 1 | AH50: 899.99 | AI50: PayPal | AJ50: North | AK50: Premium | AL50: 45050 | AM50: 899.99 | AN50: 46324.555 | AO50: Medium | BH50: TRX0248 | BI50: 45534 | BJ50: CUST032 | BK50: Sandra Phillips | BL50: P002 | BM50: Smartphone | BN50: Electronics | BO50: 2 | BP50: 699.99 | BQ50: Credit Card | BR50: North | BS50: Premium | BT50: 44421 | BU50: 1399.98 | BV50: 46324.555 | BW50: High
A51: ='Raw Data'!D45 -> Joseph Jackson | B51: ='Raw Data'!M45 -> 44707 | C51: =DATEDIF(B51,TODAY(),"Y") -> 4 | D51: =DATEDIF(B51,$B$3,"M") -> 53 | E51: =EOMONTH(B51,0) -> 44712 | I51: TRX0075 | J51: 45517 | K51: CUST020 | L51: Margaret Wright | M51: P009 | N51: Monitor | O51: Electronics | P51: 5 | Q51: 249.99 | R51: PayPal | S51: East | T51: Premium | U51: 44782 | V51: 1249.95 | W51: 46324.555 | X51: High | Z51: TRX0026 | AA51: 45661 | AB51: CUST037 | AC51: Arthur Edwards | AD51: P001 | AE51: Laptop | AF51: Electronics | AG51: 1 | AH51: 899.99 | AI51: PayPal | AJ51: North | AK51: Standard | AL51: 44752 | AM51: 899.99 | AN51: 46324.555 | AO51: Medium | BH51: TRX0074 | BI51: 45537 | BJ51: CUST023 | BK51: Paul Baker | BL51: P009 | BM51: Monitor | BN51: Electronics | BO51: 1 | BP51: 249.99 | BQ51: Debit Card | BR51: North | BS51: Premium | BT51: 45332 | BU51: 249.99 | BV51: 46324.555 | BW51: Low
A52: ='Raw Data'!D46 -> Betty Campbell | B52: ='Raw Data'!M46 -> 44582 | C52: =DATEDIF(B52,TODAY(),"Y") -> 4 | D52: =DATEDIF(B52,$B$3,"M") -> 57 | E52: =EOMONTH(B52,0) -> 44592 | I52: TRX0098 | J52: 45517 | K52: CUST026 | L52: Karen Hill | M52: P009 | N52: Monitor | O52: Electronics | P52: 3 | Q52: 249.99 | R52: PayPal | S52: North | T52: Premium | U52: 44465 | V52: 749.97 | W52: 46324.555 | X52: Medium | Z52: TRX0238 | AA52: 45668 | AB52: CUST038 | AC52: Michelle Rogers | AD52: P002 | AE52: Smartphone | AF52: Electronics | AG52: 3 | AH52: 699.99 | AI52: Cash | AJ52: North | AK52: Premium | AL52: 44602 | AM52: 2099.97 | AN52: 46324.555 | AO52: High | BH52: TRX0112 | BI52: 45544 | BJ52: CUST008 | BK52: Jennifer Taylor | BL52: P004 | BM52: Coffee Maker | BN52: Appliances | BO52: 4 | BP52: 79.99 | BQ52: Cash | BR52: North | BS52: Basic | BT52: 44530 | BU52: 319.96 | BV52: 46324.555 | BW52: Low
A53: ='Raw Data'!D47 -> Michael Brown | B53: ='Raw Data'!M47 -> 44645 | C53: =DATEDIF(B53,TODAY(),"Y") -> 4 | D53: =DATEDIF(B53,$B$3,"M") -> 55 | E53: =EOMONTH(B53,0) -> 44651 | I53: TRX0140 | J53: 45522 | K53: CUST025 | L53: Mark Carter | M53: P010 | N53: Keyboard | O53: Electronics | P53: 2 | Q53: 89.99 | R53: Cash | S53: East | T53: Premium | U53: 44972 | V53: 179.98 | W53: 46324.555 | X53: Low | Z53: TRX0022 | AA53: 45670 | AB53: CUST025 | AC53: Mark Carter | AD53: P007 | AE53: Desk | AF53: Furniture | AG53: 1 | AH53: 299.99 | AI53: Credit Card | AJ53: North | AK53: Basic | AL53: 44436 | AM53: 299.99 | AN53: 46324.555 | AO53: Low | BH53: TRX0211 | BI53: 45548 | BJ53: CUST046 | BK53: Kathleen Bennett | BL53: P010 | BM53: Keyboard | BN53: Electronics | BO53: 2 | BP53: 89.99 | BQ53: Credit Card | BR53: South | BS53: Premium | BT53: 44641 | BU53: 179.98 | BV53: 46324.555 | BW53: Low
A54: ='Raw Data'!D48 -> Julie Foster | B54: ='Raw Data'!M48 -> 44435 | C54: =DATEDIF(B54,TODAY(),"Y") -> 5 | D54: =DATEDIF(B54,$B$3,"M") -> 62 | E54: =EOMONTH(B54,0) -> 44439 | I54: TRX0132 | J54: 45523 | K54: CUST047 | L54: Gerald Murphy | M54: P001 | N54: Laptop | O54: Electronics | P54: 5 | Q54: 899.99 | R54: Debit Card | S54: East | T54: Basic | U54: 44526 | V54: 4499.95 | W54: 46324.555 | X54: High | Z54: TRX0087 | AA54: 45671 | AB54: CUST028 | AC54: Betty Campbell | AD54: P009 | AE54: Monitor | AF54: Electronics | AG54: 4 | AH54: 249.99 | AI54: Credit Card | AJ54: North | AK54: Premium | AL54: 44460 | AM54: 999.96 | AN54: 46324.555 | AO54: Medium | BH54: TRX0005 | BI54: 45550 | BJ54: CUST042 | BK54: Ruth Brooks | BL54: P003 | BM54: Headphones | BN54: Electronics | BO54: 4 | BP54: 149.99 | BQ54: Cash | BR54: North | BS54: Basic | BT54: 44909 | BU54: 599.96 | BV54: 46324.555 | BW54: Medium
... A65: ='Raw Data'!D59 -> Patricia Moore | B65: ='Raw Data'!M59 -> 44993 | C65: =DATEDIF(B65,TODAY(),"Y") -> 3 | D65: =DATEDIF(B65,$B$3,"M") -> 43 | E65: =EOMONTH(B65,0) -> 45016 | I65: TRX0195 | J65: 45551 | K65: CUST026 | L65: Karen Hill | M65: P009 | N65: Monitor | O65: Electronics | P65: 2 | Q65: 249.99 | R65: PayPal | S65: South | T65: Basic | U65: 44993 | V65: 499.98 | W65: 46324.555 | X65: Low | Z65: TRX0064 | AA65: 45758 | AB65: CUST031 | AC65: Steven Turner | AD65: P010 | AE65: Keyboard | AF65: Electronics | AG65: 3 | AH65: 89.99 | AI65: Debit Card | AJ65: North | AK65: Premium | AL65: 44878 | AM65: 269.97 | AN65: 46324.555 | AO65: Low | BH65: TRX0090 | BI65: 45605 | BJ65: CUST020 | BK65: Margaret Wright | BL65: P009 | BM65: Monitor | BN65: Electronics | BO65: 1 | BP65: 249.99 | BQ65: Credit Card | BR65: North | BS65: Premium | BT65: 44828 | BU65: 249.99 | BV65: 46324.555 | BW65: Low
A66: ='Raw Data'!D60 -> Helen Roberts | B66: ='Raw Data'!M60 -> 44851 | C66: =DATEDIF(B66,TODAY(),"Y") -> 4 | D66: =DATEDIF(B66,$B$3,"M") -> 48 | E66: =EOMONTH(B66,0) -> 44865 | I66: TRX0077 | J66: 45554 | K66: CUST019 | L66: Daniel King | M66: P010 | N66: Keyboard | O66: Electronics | P66: 5 | Q66: 89.99 | R66: Credit Card | S66: East | T66: Premium | U66: 44446 | V66: 449.95 | W66: 46324.555 | X66: Low | BH66: TRX0035 | BI66: 45607 | BJ66: CUST041 | BK66: Peter Richardson | BL66: P003 | BM66: Headphones | BN66: Electronics | BO66: 3 | BP66: 149.99 | BQ66: Cash | BR66: North | BS66: Basic | BT66: 44769 | BU66: 449.97 | BV66: 46324.555 | BW66: Low
A67: ='Raw Data'!D61 -> Emma Wilson | B67: ='Raw Data'!M61 -> 45275 | C67: =DATEDIF(B67,TODAY(),"Y") -> 2 | D67: =DATEDIF(B67,$B$3,"M") -> 34 | E67: =EOMONTH(B67,0) -> 45291 | I67: TRX0111 | J67: 45554 | K67: CUST011 | L67: William White | M67: P003 | N67: Headphones | O67: Electronics | P67: 1 | Q67: 149.99 | R67: PayPal | S67: East | T67: Standard | U67: 44482 | V67: 149.99 | W67: 46324.555 | X67: Low | BH67: TRX0149 | BI67: 45608 | BJ67: CUST027 | BK67: George Adams | BL67: P005 | BM67: Blender | BN67: Appliances | BO67: 3 | BP67: 59.99 | BQ67: Debit Card | BR67: South | BS67: Standard | BT67: 45260 | BU67: 179.97 | BV67: 46324.555 | BW67: Low
A68: ='Raw Data'!D62 -> Charles Allen | B68: ='Raw Data'!M62 -> 44802 | C68: =DATEDIF(B68,TODAY(),"Y") -> 4 | D68: =DATEDIF(B68,$B$3,"M") -> 50 | E68: =EOMONTH(B68,0) -> 44804 | I68: TRX0123 | J68: 45554 | K68: CUST041 | L68: Peter Richardson | M68: P002 | N68: Smartphone | O68: Electronics | P68: 4 | Q68: 699.99 | R68: PayPal | S68: South | T68: Basic | U68: 44618 | V68: 2799.96 | W68: 46324.555 | X68: High | BH68: TRX0073 | BI68: 45613 | BJ68: CUST032 | BK68: Sandra Phillips | BL68: P008 | BM68: Bookshelf | BN68: Furniture | BO68: 5 | BP68: 149.99 | BQ68: Cash | BR68: North | BS68: Basic | BT68: 44869 | BU68: 749.95 | BV68: 46324.555 | BW68: Medium
A69: ='Raw Data'!D63 -> Susan Green | B69: ='Raw Data'!M63 -> 44611 | C69: =DATEDIF(B69,TODAY(),"Y") -> 4 | D69: =DATEDIF(B69,$B$3,"M") -> 56 | E69: =EOMONTH(B69,0) -> 44620 | I69: TRX0177 | J69: 45559 | K69: CUST032 | L69: Sandra Phillips | M69: P001 | N69: Laptop | O69: Electronics | P69: 3 | Q69: 899.99 | R69: Credit Card | S69: North | T69: Standard | U69: 45157 | V69: 2699.97 | W69: 46324.555 | X69: High | BH69: TRX0012 | BI69: 45622 | BJ69: CUST045 | BK69: Douglas Watson | BL69: P009 | BM69: Monitor | BN69: Electronics | BO69: 5 | BP69: 249.99 | BQ69: Credit Card | BR69: North | BS69: Basic | BT69: 44873 | BU69: 1249.95 | BV69: 46324.555 | BW69: High
A70: ='Raw Data'!D64 -> David Martinez | B70: ='Raw Data'!M64 -> 44981 | C70: =DATEDIF(B70,TODAY(),"Y") -> 3 | D70: =DATEDIF(B70,$B$3,"M") -> 44 | E70: =EOMONTH(B70,0) -> 44985 | I70: TRX0203 | J70: 45572 | K70: CUST032 | L70: Sandra Phillips | M70: P003 | N70: Headphones | O70: Electronics | P70: 4 | Q70: 149.99 | R70: Credit Card | S70: North | T70: Premium | U70: 45076 | V70: 599.96 | W70: 46324.555 | X70: Medium | BH70: TRX0206 | BI70: 45623 | BJ70: CUST014 | BK70: Linda Martin | BL70: P008 | BM70: Bookshelf | BN70: Furniture | BO70: 2 | BP70: 149.99 | BQ70: Cash | BR70: South | BS70: Standard | BT70: 45101 | BU70: 299.98 | BV70: 46324.555 | BW70: Low
A71: ='Raw Data'!D65 -> Margaret Wright | B71: ='Raw Data'!M65 -> 44421 | C71: =DATEDIF(B71,TODAY(),"Y") -> 5 | D71: =DATEDIF(B71,$B$3,"M") -> 62 | E71: =EOMONTH(B71,0) -> 44439 | I71: TRX0055 | J71: 45573 | K71: CUST016 | L71: Elizabeth Hall | M71: P002 | N71: Smartphone | O71: Electronics | P71: 2 | Q71: 699.99 | R71: Debit Card | S71: East | T71: Premium | U71: 45274 | V71: 1399.98 | W71: 46324.555 | X71: High | BH71: TRX0045 | BI71: 45627 | BJ71: CUST021 | BK71: Kevin Scott | BL71: P007 | BM71: Desk | BN71: Furniture | BO71: 3 | BP71: 299.99 | BQ71: Cash | BR71: South | BS71: Premium | BT71: 44659 | BU71: 899.97 | BV71: 46324.555 | BW71: Medium
A72: ='Raw Data'!D66 -> Michael Brown | B72: ='Raw Data'!M66 -> 45389 | C72: =DATEDIF(B72,TODAY(),"Y") -> 2 | D72: =DATEDIF(B72,$B$3,"M") -> 30 | E72: =EOMONTH(B72,0) -> 45412 | I72: TRX0158 | J72: 45579 | K72: CUST027 | L72: George Adams | M72: P001 | N72: Laptop | O72: Electronics | P72: 3 | Q72: 899.99 | R72: PayPal | S72: West | T72: Basic | U72: 45215 | V72: 2699.97 | W72: 46324.555 | X72: High | BH72: TRX0133 | BI72: 45627 | BJ72: CUST013 | BK72: Joseph Jackson | BL72: P003 | BM72: Headphones | BN72: Electronics | BO72: 2 | BP72: 149.99 | BQ72: Cash | BR72: South | BS72: Premium | BT72: 44475 | BU72: 299.98 | BV72: 46324.555 | BW72: Low
A73: ='Raw Data'!D67 -> Barbara Young | B73: ='Raw Data'!M67 -> 45161 | C73: =DATEDIF(B73,TODAY(),"Y") -> 3 | D73: =DATEDIF(B73,$B$3,"M") -> 38 | E73: =EOMONTH(B73,0) -> 45169 | I73: TRX0173 | J73: 45581 | K73: CUST018 | L73: Barbara Young | M73: P002 | N73: Smartphone | O73: Electronics | P73: 5 | Q73: 699.99 | R73: Cash | S73: East | T73: Standard | U73: 45008 | V73: 3499.95 | W73: 46324.555 | X73: High | BH73: TRX0066 | BI73: 45630 | BJ73: CUST024 | BK73: Dorothy Nelson | BL73: P002 | BM73: Smartphone | BN73: Electronics | BO73: 4 | BP73: 699.99 | BQ73: Credit Card | BR73: North | BS73: Premium | BT73: 44703 | BU73: 2799.96 | BV73: 46324.555 | BW73: High
A74: ='Raw Data'!D68 -> Raymond Ross | B74: ='Raw Data'!M68 -> 44509 | C74: =DATEDIF(B74,TODAY(),"Y") -> 4 | D74: =DATEDIF(B74,$B$3,"M") -> 59 | E74: =EOMONTH(B74,0) -> 44530 | I74: TRX0034 | J74: 45581 | K74: CUST049 | L74: Raymond Ross | M74: P002 | N74: Smartphone | O74: Electronics | P74: 4 | Q74: 699.99 | R74: Credit Card | S74: Central | T74: Basic | U74: 45385 | V74: 2799.96 | W74: 46324.555 | X74: High | BH74: TRX0032 | BI74: 45638 | BJ74: CUST041 | BK74: Peter Richardson | BL74: P001 | BM74: Laptop | BN74: Electronics | BO74: 2 | BP74: 899.99 | BQ74: Cash | BR74: North | BS74: Basic | BT74: 44406 | BU74: 1799.98 | BV74: 46324.555 | BW74: High
A75: ='Raw Data'!D69 -> Joseph Jackson | B75: ='Raw Data'!M69 -> 44909 | C75: =DATEDIF(B75,TODAY(),"Y") -> 3 | D75: =DATEDIF(B75,$B$3,"M") -> 46 | E75: =EOMONTH(B75,0) -> 44926 | I75: TRX0189 | J75: 45581 | K75: CUST040 | L75: Sharon Butler | M75: P001 | N75: Laptop | O75: Electronics | P75: 1 | Q75: 899.99 | R75: Credit Card | S75: East | T75: Standard | U75: 45369 | V75: 899.99 | W75: 46324.555 | X75: Medium | BH75: TRX0046 | BI75: 45646 | BJ75: CUST003 | BK75: Michael Brown | BL75: P008 | BM75: Bookshelf | BN75: Furniture | BO75: 2 | BP75: 149.99 | BQ75: Cash | BR75: South | BS75: Basic | BT75: 45239 | BU75: 299.98 | BV75: 46324.555 | BW75: Low
...

Sheet CUSTOMER ANALYSIS
A1: Customer_ID | B1: Customer_Name | C1: Total_Spending | D1: Transaction_Count | E1: Total_Quantity | F1: Average_Transaction | G1: Customer_Rank | H1: Customer_Category
A2: {=_xlfn._xlws.SORT(_xlfn.UNIQUE(tblTransactions[Customer_ID]))} -> CUST001 | B2: =_xlfn.XLOOKUP(A2,tblTransactions[Customer_ID],tblTransactions[Customer_Name],"Not Found") -> John Smith | C2: =SUMIF(tblTransactions[Customer_ID],A2,tblTransactions[Total_Amount]) -> 599.96 | D2: =COUNTIF(tblTransactions[Customer_ID],A2) -> 1 | E2: =SUMIF(tblTransactions[Customer_ID],A2,tblTransactions[Quantity]) -> 4 | F2: =IFERROR(C2/D2,0) -> 599.96 | G2: =_xlfn.RANK.EQ(C2,$C$2:$C$51,0) -> 47 | H2: =IF(G2<=5,"Top 5 Customer",IF(C2>=10000,"High Value","Regular")) -> Regular
A3: CUST002 | B3: =_xlfn.XLOOKUP(A3,tblTransactions[Customer_ID],tblTransactions[Customer_Name],"Not Found") -> Emma Wilson | C3: =SUMIF(tblTransactions[Customer_ID],A3,tblTransactions[Total_Amount]) -> 1229.88 | D3: =COUNTIF(tblTransactions[Customer_ID],A3) -> 5 | E3: =SUMIF(tblTransactions[Customer_ID],A3,tblTransactions[Quantity]) -> 12 | F3: =IFERROR(C3/D3,0) -> 245.976 | G3: =_xlfn.RANK.EQ(C3,$C$2:$C$51,0) -> 44 | H3: =IF(G3<=5,"Top 5 Customer",IF(C3>=10000,"High Value","Regular")) -> Regular
A4: CUST003 | B4: =_xlfn.XLOOKUP(A4,tblTransactions[Customer_ID],tblTransactions[Customer_Name],"Not Found") -> Michael Brown | C4: =SUMIF(tblTransactions[Customer_ID],A4,tblTransactions[Total_Amount]) -> 6169.74 | D4: =COUNTIF(tblTransactions[Customer_ID],A4) -> 9 | E4: =SUMIF(tblTransactions[Customer_ID],A4,tblTransactions[Quantity]) -> 26 | F4: =IFERROR(C4/D4,0) -> 685.52667 | G4: =_xlfn.RANK.EQ(C4,$C$2:$C$51,0) -> 14 | H4: =IF(G4<=5,"Top 5 Customer",IF(C4>=10000,"High Value","Regular")) -> Regular
A5: CUST004 | B5: =_xlfn.XLOOKUP(A5,tblTransactions[Customer_ID],tblTransactions[Customer_Name],"Not Found") -> Sarah Davis | C5: =SUMIF(tblTransactions[Customer_ID],A5,tblTransactions[Total_Amount]) -> 5499.81 | D5: =COUNTIF(tblTransactions[Customer_ID],A5) -> 5 | E5: =SUMIF(tblTransactions[Customer_ID],A5,tblTransactions[Quantity]) -> 19 | F5: =IFERROR(C5/D5,0) -> 1099.962 | G5: =_xlfn.RANK.EQ(C5,$C$2:$C$51,0) -> 19 | H5: =IF(G5<=5,"Top 5 Customer",IF(C5>=10000,"High Value","Regular")) -> Regular
A6: CUST005 | B6: =_xlfn.XLOOKUP(A6,tblTransactions[Customer_ID],tblTransactions[Customer_Name],"Not Found") -> James Johnson | C6: =SUMIF(tblTransactions[Customer_ID],A6,tblTransactions[Total_Amount]) -> 179.97 | D6: =COUNTIF(tblTransactions[Customer_ID],A6) -> 1 | E6: =SUMIF(tblTransactions[Customer_ID],A6,tblTransactions[Quantity]) -> 3 | F6: =IFERROR(C6/D6,0) -> 179.97 | G6: =_xlfn.RANK.EQ(C6,$C$2:$C$51,0) -> 50 | H6: =IF(G6<=5,"Top 5 Customer",IF(C6>=10000,"High Value","Regular")) -> Regular
A7: CUST006 | B7: =_xlfn.XLOOKUP(A7,tblTransactions[Customer_ID],tblTransactions[Customer_Name],"Not Found") -> Lisa Anderson | C7: =SUMIF(tblTransactions[Customer_ID],A7,tblTransactions[Total_Amount]) -> 2039.8 | D7: =COUNTIF(tblTransactions[Customer_ID],A7) -> 5 | E7: =SUMIF(tblTransactions[Customer_ID],A7,tblTransactions[Quantity]) -> 20 | F7: =IFERROR(C7/D7,0) -> 407.96 | G7: =_xlfn.RANK.EQ(C7,$C$2:$C$51,0) -> 36 | H7: =IF(G7<=5,"Top 5 Customer",IF(C7>=10000,"High Value","Regular")) -> Regular
A8: CUST007 | B8: =_xlfn.XLOOKUP(A8,tblTransactions[Customer_ID],tblTransactions[Customer_Name],"Not Found") -> David Martinez | C8: =SUMIF(tblTransactions[Customer_ID],A8,tblTransactions[Total_Amount]) -> 1809.84 | D8: =COUNTIF(tblTransactions[Customer_ID],A8) -> 6 | E8: =SUMIF(tblTransactions[Customer_ID],A8,tblTransactions[Quantity]) -> 16 | F8: =IFERROR(C8/D8,0) -> 301.64 | G8: =_xlfn.RANK.EQ(C8,$C$2:$C$51,0) -> 39 | H8: =IF(G8<=5,"Top 5 Customer",IF(C8>=10000,"High Value","Regular")) -> Regular
A9: CUST008 | B9: =_xlfn.XLOOKUP(A9,tblTransactions[Customer_ID],tblTransactions[Customer_Name],"Not Found") -> Jennifer Taylor | C9: =SUMIF(tblTransactions[Customer_ID],A9,tblTransactions[Total_Amount]) -> 4739.85 | D9: =COUNTIF(tblTransactions[Customer_ID],A9) -> 4 | E9: =SUMIF(tblTransactions[Customer_ID],A9,tblTransactions[Quantity]) -> 15 | F9: =IFERROR(C9/D9,0) -> 1184.9625 | G9: =_xlfn.RANK.EQ(C9,$C$2:$C$51,0) -> 24 | H9: =IF(G9<=5,"Top 5 Customer",IF(C9>=10000,"High Value","Regular")) -> Regular
A10: CUST009 | B10: =_xlfn.XLOOKUP(A10,tblTransactions[Customer_ID],tblTransactions[Customer_Name],"Not Found") -> Robert Thomas | C10: =SUMIF(tblTransactions[Customer_ID],A10,tblTransactions[Total_Amount]) -> 3509.9 | D10: =COUNTIF(tblTransactions[Customer_ID],A10) -> 5 | E10: =SUMIF(tblTransactions[Customer_ID],A10,tblTransactions[Quantity]) -> 10 | F10: =IFERROR(C10/D10,0) -> 701.98 | G10: =_xlfn.RANK.EQ(C10,$C$2:$C$51,0) -> 32 | H10: =IF(G10<=5,"Top 5 Customer",IF(C10>=10000,"High Value","Regular")) -> Regular
A11: CUST010 | B11: =_xlfn.XLOOKUP(A11,tblTransactions[Customer_ID],tblTransactions[Customer_Name],"Not Found") -> Maria Garcia | C11: =SUMIF(tblTransactions[Customer_ID],A11,tblTransactions[Total_Amount]) -> 1909.93 | D11: =COUNTIF(tblTransactions[Customer_ID],A11) -> 4 | E11: =SUMIF(tblTransactions[Customer_ID],A11,tblTransactions[Quantity]) -> 7 | F11: =IFERROR(C11/D11,0) -> 477.4825 | G11: =_xlfn.RANK.EQ(C11,$C$2:$C$51,0) -> 38 | H11: =IF(G11<=5,"Top 5 Customer",IF(C11>=10000,"High Value","Regular")) -> Regular
A12: CUST011 | B12: =_xlfn.XLOOKUP(A12,tblTransactions[Customer_ID],tblTransactions[Customer_Name],"Not Found") -> William White | C12: =SUMIF(tblTransactions[Customer_ID],A12,tblTransactions[Total_Amount]) -> 4749.91 | D12: =COUNTIF(tblTransactions[Customer_ID],A12) -> 3 | E12: =SUMIF(tblTransactions[Customer_ID],A12,tblTransactions[Quantity]) -> 9 | F12: =IFERROR(C12/D12,0) -> 1583.3033 | G12: =_xlfn.RANK.EQ(C12,$C$2:$C$51,0) -> 23 | H12: =IF(G12<=5,"Top 5 Customer",IF(C12>=10000,"High Value","Regular")) -> Regular
A13: CUST012 | B13: =_xlfn.XLOOKUP(A13,tblTransactions[Customer_ID],tblTransactions[Customer_Name],"Not Found") -> Patricia Moore | C13: =SUMIF(tblTransactions[Customer_ID],A13,tblTransactions[Total_Amount]) -> 9799.73 | D13: =COUNTIF(tblTransactions[Customer_ID],A13) -> 8 | E13: =SUMIF(tblTransactions[Customer_ID],A13,tblTransactions[Quantity]) -> 27 | F13: =IFERROR(C13/D13,0) -> 1224.9662 | G13: =_xlfn.RANK.EQ(C13,$C$2:$C$51,0) -> 4 | H13: =IF(G13<=5,"Top 5 Customer",IF(C13>=10000,"High Value","Regular")) -> Top 5 Customer
A14: CUST013 | B14: =_xlfn.XLOOKUP(A14,tblTransactions[Customer_ID],tblTransactions[Customer_Name],"Not Found") -> Joseph Jackson | C14: =SUMIF(tblTransactions[Customer_ID],A14,tblTransactions[Total_Amount]) -> 6949.84 | D14: =COUNTIF(tblTransactions[Customer_ID],A14) -> 5 | E14: =SUMIF(tblTransactions[Customer_ID],A14,tblTransactions[Quantity]) -> 16 | F14: =IFERROR(C14/D14,0) -> 1389.968 | G14: =_xlfn.RANK.EQ(C14,$C$2:$C$51,0) -> 10 | H14: =IF(G14<=5,"Top 5 Customer",IF(C14>=10000,"High Value","Regular")) -> Regular
... A51: CUST050 | B51: =_xlfn.XLOOKUP(A51,tblTransactions[Customer_ID],tblTransactions[Customer_Name],"Not Found") -> Julie Foster | C51: =SUMIF(tblTransactions[Customer_ID],A51,tblTransactions[Total_Amount]) -> 239.96 | D51: =COUNTIF(tblTransactions[Customer_ID],A51) -> 1 | E51: =SUMIF(tblTransactions[Customer_ID],A51,tblTransactions[Quantity]) -> 4 | F51: =IFERROR(C51/D51,0) -> 239.96 | G51: =_xlfn.RANK.EQ(C51,$C$2:$C$51,0) -> 49 | H51: =IF(G51<=5,"Top 5 Customer",IF(C51>=10000,"High Value","Regular")) -> Regular

Sheet Product Frequency AnalysisProdu
A1: Customer Name | B1: Name Frequency | C1: Product_Name | D1: Transaction_Count | E1: Total_Units_Sold | F1: Total_Revenue | H1: GOAL SEEK ANALYSIS
A2: {=_xlfn._xlws.SORT(_xlfn.UNIQUE(tblTransactions[Customer_Name]))} -> Arthur Edwards | B2: =COUNTIF(tblTransactions[Customer_Name],A2) -> 3 | C2: {=_xlfn._xlws.SORT(_xlfn.UNIQUE(tblTransactions[Product_Name]))} -> Blender | D2: =COUNTIF(tblTransactions[Product_Name],C2) -> 29 | E2: =SUMIF(tblTransactions[Product_Name],C2,tblTransactions[Quantity]) -> 87 | F2: =SUMIF(tblTransactions[Product_Name],C2,tblTransactions[Total_Amount]) -> 5219.13
A3: Barbara Young | B3: =COUNTIF(tblTransactions[Customer_Name],A3) -> 5 | C3: Bookshelf | D3: =COUNTIF(tblTransactions[Product_Name],C3) -> 35 | E3: =SUMIF(tblTransactions[Product_Name],C3,tblTransactions[Quantity]) -> 102 | F3: =SUMIF(tblTransactions[Product_Name],C3,tblTransactions[Total_Amount]) -> 15298.98 | H3: Unit Price | I3: 100
A4: Betty Campbell | B4: =COUNTIF(tblTransactions[Customer_Name],A4) -> 5 | C4: Coffee Maker | D4: =COUNTIF(tblTransactions[Product_Name],C4) -> 14 | E4: =SUMIF(tblTransactions[Product_Name],C4,tblTransactions[Quantity]) -> 39 | F4: =SUMIF(tblTransactions[Product_Name],C4,tblTransactions[Total_Amount]) -> 3119.61
A5: Carol Evans | B5: =COUNTIF(tblTransactions[Customer_Name],A5) -> 3 | C5: Desk | D5: =COUNTIF(tblTransactions[Product_Name],C5) -> 26 | E5: =SUMIF(tblTransactions[Product_Name],C5,tblTransactions[Quantity]) -> 78 | F5: =SUMIF(tblTransactions[Product_Name],C5,tblTransactions[Total_Amount]) -> 23399.22 | H5: Quantity | I5: 200
A6: Charles Allen | B6: =COUNTIF(tblTransactions[Customer_Name],A6) -> 9 | C6: Headphones | D6: =COUNTIF(tblTransactions[Product_Name],C6) -> 16 | E6: =SUMIF(tblTransactions[Product_Name],C6,tblTransactions[Quantity]) -> 47 | F6: =SUMIF(tblTransactions[Product_Name],C6,tblTransactions[Total_Amount]) -> 7049.53
A7: Cynthia Price | B7: =COUNTIF(tblTransactions[Customer_Name],A7) -> 5 | C7: Keyboard | D7: =COUNTIF(tblTransactions[Product_Name],C7) -> 34 | E7: =SUMIF(tblTransactions[Product_Name],C7,tblTransactions[Quantity]) -> 89 | F7: =SUMIF(tblTransactions[Product_Name],C7,tblTransactions[Total_Amount]) -> 8009.11
A8: Daniel King | B8: =COUNTIF(tblTransactions[Customer_Name],A8) -> 7 | C8: Laptop | D8: =COUNTIF(tblTransactions[Product_Name],C8) -> 24 | E8: =SUMIF(tblTransactions[Product_Name],C8,tblTransactions[Quantity]) -> 75 | F8: =SUMIF(tblTransactions[Product_Name],C8,tblTransactions[Total_Amount]) -> 67499.25 | H8: Total Revenue | I8: =I3*I5 -> 20000
A9: David Martinez | B9: =COUNTIF(tblTransactions[Customer_Name],A9) -> 6 | C9: Monitor | D9: =COUNTIF(tblTransactions[Product_Name],C9) -> 26 | E9: =SUMIF(tblTransactions[Product_Name],C9,tblTransactions[Quantity]) -> 88 | F9: =SUMIF(tblTransactions[Product_Name],C9,tblTransactions[Total_Amount]) -> 21999.12
A10: Dennis Gray | B10: =COUNTIF(tblTransactions[Customer_Name],A10) -> 2 | C10: Office Chair | D10: =COUNTIF(tblTransactions[Product_Name],C10) -> 15 | E10: =SUMIF(tblTransactions[Product_Name],C10,tblTransactions[Quantity]) -> 52 | F10: =SUMIF(tblTransactions[Product_Name],C10,tblTransactions[Total_Amount]) -> 10399.48
A11: Dorothy Nelson | B11: =COUNTIF(tblTransactions[Customer_Name],A11) -> 6 | C11: Smartphone | D11: =COUNTIF(tblTransactions[Product_Name],C11) -> 31 | E11: =SUMIF(tblTransactions[Product_Name],C11,tblTransactions[Quantity]) -> 96 | F11: =SUMIF(tblTransactions[Product_Name],C11,tblTransactions[Total_Amount]) -> 67199.04
A12: Douglas Watson | B12: =COUNTIF(tblTransactions[Customer_Name],A12) -> 4
A13: Edward Mitchell | B13: =COUNTIF(tblTransactions[Customer_Name],A13) -> 6
A14: Elizabeth Hall | B14: =COUNTIF(tblTransactions[Customer_Name],A14) -> 4
A15: Emma Wilson | B15: =COUNTIF(tblTransactions[Customer_Name],A15) -> 5
A16: Frank Torres | B16: =COUNTIF(tblTransactions[Customer_Name],A16) -> 5
A17: George Adams | B17: =COUNTIF(tblTransactions[Customer_Name],A17) -> 3
A18: Gerald Murphy | B18: =COUNTIF(tblTransactions[Customer_Name],A18) -> 4
A19: Harry Morgan | B19: =COUNTIF(tblTransactions[Customer_Name],A19) -> 4
A20: Helen Roberts | B20: =COUNTIF(tblTransactions[Customer_Name],A20) -> 7
A21: James Johnson | B21: =COUNTIF(tblTransactions[Customer_Name],A21) -> 1
A22: Jennifer Taylor | B22: =COUNTIF(tblTransactions[Customer_Name],A22) -> 4
A23: John Smith | B23: =COUNTIF(tblTransactions[Customer_Name],A23) -> 1
... A51: William White | B51: =COUNTIF(tblTransactions[Customer_Name],A51) -> 3

Sheet Visualizations
A2: Row Labels | B2: Sum of Total_Amount | D2: Row Labels | E2: Sum of Total_Amount | G2: Row Labels | H2: Sum of Total_Amount | I2: Sum of Quantity
A3: Basic | B3: 62177.81 | D3: 2024 | E3: 160444.73 | G3: Blender | H3: 5219.13 | I3: 87
A4: TRX0002 | B4: 899.97 | D4: Apr | E4: 20919.33 | G4: Bookshelf | H4: 15298.98 | I4: 102
A5: TRX0005 | B5: 599.96 | D5: May | E5: 17039.35 | G5: Coffee Maker | H5: 3119.61 | I5: 39
A6: TRX0007 | B6: 179.98 | D6: Jun | E6: 19299.45 | G6: Desk | H6: 23399.22 | I6: 78
A7: TRX0009 | B7: 1399.98 | D7: Jul | E7: 18479.4 | G7: Headphones | H7: 7049.53 | I7: 47
A8: TRX0012 | B8: 1249.95 | D8: Aug | E8: 15759.43 | G8: Keyboard | H8: 8009.11 | I8: 89
A9: TRX0013 | B9: 2699.97 | D9: Sep | E9: 12989.51 | G9: Laptop | H9: 67499.25 | I9: 75
A10: TRX0014 | B10: 119.98 | D10: Oct | E10: 20609.52 | G10: Monitor | H10: 21999.12 | I10: 88
A11: TRX0021 | B11: 239.97 | D11: Nov | E11: 12309.44 | G11: Office Chair | H11: 10399.48 | I11: 52
A12: TRX0022 | B12: 299.99 | D12: Dec | E12: 23039.3 | G12: Smartphone | H12: 67199.04 | I12: 96
A13: TRX0025 | B13: 359.96 | D13: 2025 | E13: 68747.74 | G13: Grand Total | H13: 229192.47 | I13: 753
A14: TRX0028 | B14: 119.98 | D14: Jan | E14: 25799.15
A15: TRX0030 | B15: 3599.96 | D15: Feb | E15: 16069.38
A16: TRX0031 | B16: 449.97 | D16: Mar | E16: 19899.38 | G16: Row Labels | H16: Sum of Total_Amount
A17: TRX0032 | B17: 1799.98 | D17: Apr | E17: 6979.83 | G17: Appliances | H17: 8338.74
A18: TRX0034 | B18: 2799.96 | D18: Grand Total | E18: 229192.47 | G18: Electronics | H18: 171756.05
A19: TRX0035 | B19: 449.97 | G19: Furniture | H19: 49097.68
A20: TRX0039 | B20: 239.97 | G20: Grand Total | H20: 229192.47
A21: TRX0040 | B21: 1499.95 | D21: Row Labels | E21: Sum of Total_Amount
A22: TRX0046 | B22: 299.98 | D22: Central | E22: 41288.34
A23: TRX0048 | B23: 599.98 | D23: East | E23: 59288.39
A24: TRX0051 | B24: 899.97 | D24: North | E24: 50808.31
A25: TRX0054 | B25: 799.96 | D25: South | E25: 36398.75
A26: TRX0059 | B26: 1499.95 | D26: West | E26: 41408.68
A27: TRX0065 | B27: 299.98 | D27: Grand Total | E27: 229192.47
A28: TRX0069 | B28: 179.98
A29: TRX0070 | B29: 399.95
A30: TRX0073 | B30: 749.95
A31: TRX0079 | B31: 269.97
A32: TRX0086 | B32: 149.99
A33: TRX0089 | B33: 599.97
A34: TRX0095 | B34: 299.98
A35: TRX0097 | B35: 399.98
A36: TRX0102 | B36: 79.99
A37: TRX0103 | B37: 179.98
A38: TRX0105 | B38: 1499.95
A39: TRX0110 | B39: 299.95
... A256: Grand Total | B256: 229192.47

Sheet Regression
A1: SUMMARY OUTPUT
A3: Regression Statistics
A4: Multiple R | B4: 0.92884475
A5: R Square | B5: 0.86275258
A6: Adjusted R Square | B6: 0.86164126
A7: Standard Error | B7: 384.0375
A8: Observations | B8: 250
A10: ANOVA
B11: df | C11: SS | D11: MS | E11: F | F11: Significance F
A12: Regression | B12: 2 | C12: 2.2899515e+08 | D12: 1.1449757e+08 | E12: 776.33474 | F12: 3.032279e-107
A13: Residual | B13: 247 | C13: 36428746 | D13: 147484.8
A14: Total | B14: 249 | C14: 2.6542389e+08
B16: Coefficients | C16: Standard Error | D16: t Stat | E16: P-value | F16: Lower 95% | G16: Upper 95% | H16: Lower 95.0% | I16: Upper 95.0%
A17: Intercept | B17: -931.80859 | C17: 64.176586 | D17: -14.519448 | E17: 5.9491879e-35 | F17: -1058.2117 | G17: -805.40543 | H17: -1058.2117 | I17: -805.40543
A18: Quantity | B18: 314.14588 | C18: 18.242562 | D18: 17.220491 | E18: 3.4020508e-44 | F18: 278.21506 | G18: 350.0767 | H18: 278.21506 | I18: 350.0767
A19: Unit_Price | B19: 3.041666 | C19: 0.088733343 | D19: 34.278727 | E19: 7.2446245e-96 | F19: 2.8668955 | G19: 3.2164365 | H19: 2.8668955 | I19: 3.2164365

Sheet List Comparison & Abbreviations
A1: Product List 1 | B1: Product List 2 | C1: Comparison Result | D1: List 2 Comparison
A2: Laptop | B2: Mobile | C2: =IF(COUNTIF($B$2:$B$7,A2)>0,"Common","Not Found") -> Not Found | D2: =IF(COUNTIF($A$2:$A$7,B2)>0,"Common","Not Found") -> Common
A3: Mobile | B3: Keyboard | C3: =IF(COUNTIF($B$2:$B$7,A3)>0,"Common","Not Found") -> Common | D3: =IF(COUNTIF($A$2:$A$7,B3)>0,"Common","Not Found") -> Common
A4: Keyboard | B4: Headphones | C4: =IF(COUNTIF($B$2:$B$7,A4)>0,"Common","Not Found") -> Common | D4: =IF(COUNTIF($A$2:$A$7,B4)>0,"Common","Not Found") -> Not Found
A5: Mouse | B5: Mouse | C5: =IF(COUNTIF($B$2:$B$7,A5)>0,"Common","Not Found") -> Common | D5: =IF(COUNTIF($A$2:$A$7,B5)>0,"Common","Not Found") -> Common
A6: Monitor | B6: Webcam | C6: =IF(COUNTIF($B$2:$B$7,A6)>0,"Common","Not Found") -> Not Found | D6: =IF(COUNTIF($A$2:$A$7,B6)>0,"Common","Not Found") -> Not Found
A7: Printer | B7: Printer | C7: =IF(COUNTIF($B$2:$B$7,A7)>0,"Common","Not Found") -> Common | D7: =IF(COUNTIF($A$2:$A$7,B7)>0,"Common","Not Found") -> Common
A9: Create Abbreviations
A10: Full Name | B10: Abbreviation
A11: Home Appliances | B11: =LEFT(A11,1)&MID(A11,FIND(" ",A11)+1,1) -> HA
A12: Personal Care | B12: =LEFT(A12,1)&MID(A12,FIND(" ",A12)+1,1) -> PC
A13: Office Supplies | B13: =LEFT(A13,1)&MID(A13,FIND(" ",A13)+1,1) -> OS
A14: Sports Equipment | B14: =LEFT(A14,1)&MID(A14,FIND(" ",A14)+1,1) -> SE
A15: Mobile Accessories | B15: =LEFT(A15,1)&MID(A15,FIND(" ",A15)+1,1) -> MA

Sheet Scenario Summary 
B2: Scenario Summary
D3: Current Values: | E3: Base Case | F3: Best Case | G3: Worst Case
E4: Created by ASUS on 28-10-2026 Modified by ASUS on 28-10-2026 | F4: Created by ASUS on 28-10-2026 Modified by ASUS on 28-10-2026 | G4: Created by ASUS on 28-10-2026 Modified by ASUS on 28-10-2026
B5: Changing Cells:
C6: $C$262 | D6: 150 | E6: 150 | F6: 150 | G6: 150
C7: $C$263 | D7: 120 | E7: 120 | F7: 120 | G7: 120
C8: $D$262 | D8: 70 | E8: 70 | F8: 70 | G8: 70
C9: $D$263 | D9: 90 | E9: 90 | F9: 90 | G9: 90
B10: Result Cells:
C11: $A$266
B12: Notes: Current Values column represents values of changing cells at
B13: time Scenario Summary Report was created. Changing cells for each
B14: scenario are highlighted in gray.

Sheet Dashboard
A1: DATA INTELLIGENCE DASHBOARD
K5: Customer Transaction Analysis | Revenue | Products | Regions | Customer Insights
A8: Total Revenue | C8: =SUM(tblTransactions[Total_Amount]) -> 229192.47
A10: Total Transactions | C10: =COUNTA(tblTransactions[Transaction_ID]) -> 250
A12: Unique Customers | C12: =COUNTA(_xlfn.UNIQUE(tblTransactions[Customer_ID])) -> 50
A14: Total Units Sold | C14: =SUM(tblTransactions[Quantity]) -> 753
A16: Average Transaction Value | C16: =AVERAGE(tblTransactions[Total_Amount]) -> 916.76988
A18: Top-Selling Product | C18: =INDEX('Product Frequency AnalysisProdu'!C1:C11,MATCH(MAX('Product Frequency AnalysisProdu'!E1:E11),'Product Frequency AnalysisProdu'!E1:E11,0)) -> Bookshelf

Sheet Final Report
A1: RETAIL TRANSACTION DATA ANALYSIS — FINAL REPORT
A5: Project: Retail Transaction Dataset Analysis
A7: Report Date | B7: =TODAY() -> 46324
A10: 1. EXECUTIVE SUMMARY
A12: This project analyzes retail transaction data to understand sales performance, customer purchasing behavior, product demand, and regional performance. Excel functions, data analysis techniques, and visualizations are used to identify important business insights and support data-driven decision-making.
A17: 2. KEY PERFORMANCE INDICATORS
A20: Total Revenue | B20: =SUM(tblTransactions[Total_Amount]) -> 229192.47
A21: Total Transactions | B21: =COUNTA(tblTransactions[Transaction_ID]) -> 250
A22: Total Units Sold | B22: =SUM(tblTransactions[Quantity]) -> 753
A23: Unique Customers | B23: =COUNTA(_xlfn.UNIQUE(tblTransactions[Customer_ID])) -> 50
A24: Unique Products | B24: =COUNTA(_xlfn.UNIQUE(tblTransactions[Product_Name])) -> 10
A25: Average Transaction Value | B25: =AVERAGE(tblTransactions[Total_Amount]) -> 916.76988
A28: 3. PRODUCT PERFORMANCE ANALYSIS
A31: Top-Selling Product | B31: =INDEX('Product Frequency AnalysisProdu'!C1:C11,MATCH(MAX('Product Frequency AnalysisProdu'!E1:E11),'Product Frequency AnalysisProdu'!E1:E11,0)) -> Bookshelf
A32: Highest Revenue Product | B32: =INDEX('Product Frequency AnalysisProdu'!C1:C11,MATCH(MAX('Product Frequency AnalysisProdu'!F1:F11),'Product Frequency AnalysisProdu'!F1:F11,0)) -> Laptop
A33: Total Units Sold | B33: =SUM(tblTransactions[Quantity]) -> 753
A34: Product Revenue | B34: =SUM(tblTransactions[Total_Amount]) -> 229192.47
A37: 4. CUSTOMER ANALYSIS
A40: Most Frequent Customer | B40: =INDEX('Product Frequency AnalysisProdu'!A1:A51,MATCH(MAX('Product Frequency AnalysisProdu'!B1:B51),'Product Frequency AnalysisProdu'!B1:B51,0)) -> Mark Carter
A41: Highest Spending Customer | B41: =INDEX('CUSTOMER ANALYSIS'!B2:B51,MATCH(MAX('CUSTOMER ANALYSIS'!C1:C51),'CUSTOMER ANALYSIS'!C1:C51,0)) -> Karen Hill
